Workbook

Sheet PUBG
B1: Sniper Rifle damage stats:
B3: Weapon | C3: Base Damage | D3: Fire Rate | E3: DPS | F3: Time to Kill | G3: Shots to Kill (Chest) | H3: Shots to Kill (Head) | I3: Availability
B4: S686 | C4: 216 | D4: 0.2 | E4: 1080 | F4: 0 | G4: 1 | H4: 1 | I4: All
B5: S1897 | C5: 216 | D5: 0.75 | E5: 288 | F5: 0 | G5: 1 | H5: 1 | I5: All
B6: S12k | C6: 198 | D6: 0.25 | E6: 792 | F6: 0 | G6: 1 | H6: 1 | I6: All
B7: AWM | C7: 120 | D7: 1.85 | E7: 65 | F7: 1.85 | G7: 2 | H7: 1 | I7: Crate Only | J7: The new Beryl M762, now available on all maps, brings a much-needed second option for 7.62 Assault Rifles.
B8: M24 | C8: 88 | D8: 1.8 | E8: 49 | F8: 1.8 | G8: 2 | H8: 1 | I8: Crate Only (Non-Crate on Sanhok)
B9: Kar98k | C9: 75 | D9: 1.9 | E9: 39 | F9: 3.8 | G9: 3 | H9: 1 | I9: All
B10: Win94 | C10: 66 | D10: 0.6 | E10: 110 | F10: 1.2 | G10: 3 | H10: 2 | I10: Miramar Only
B11: MK14* | C11: 61 | D11: 0.09 | E11: 678 | F11: 0.18 | G11: 3 | H11: 2 | I11: Crate Only
B12: SLR | C12: 58 | D12: 0.1 | E12: 580 | F12: 0.2 | G12: 3 | H12: 2 | I12: All
B13: SKS | C13: 53 | D13: 0.1 | E13: 530 | F13: 0.2 | G13: 3 | H13: 2 | I13: All
B14: DP-28 | C14: 51 | D14: 0.109 | E14: 468 | F14: 0.33 | G14: 4 | H14: 2 | I14: All
B15: Groza | C15: 49 | D15: 0.08 | E15: 613 | F15: 0.24 | G15: 4 | H15: 2 | I15: Crate Only
B16: Mk47 Mutant | C16: 49 | D16: 0.1 | E16: 490 | F16: 0.3 | G16: 4 | H16: 2 | I16: All
B17: AKM | C17: 49 | D17: 0.1 | E17: 490 | F17: 0.3 | G17: 4 | H17: 2 | I17: All
B18: QBU88 | C18: 48 | D18: 0.1 | E18: 480 | F18: 0.3 | G18: 4 | H18: 2 | I18: Sanhok Only
B19: Beryl M762 | C19: 47 | D19: 0.086 | E19: 547 | F19: 0.26 | G19: 4 | H19: 2 | I19: All
... B21: M249 | C21: 45 | D21: 0.075 | E21: 600 | F21: 0.23 | G21: 4 | H21: 3 | I21: Crate Only
B22: M16A4 | C22: 43 | D22: 0.075 | E22: 573 | F22: 0.22 / 0.26 | G22: 4 | H22: 2 | I22: All
B23: AUG A3 | C23: 43 | D23: 0.086 | E23: 502 | F23: 0.26 | G23: 4 | H23: 2 | I23: Crate Only
B24: M416 | C24: 43 | D24: 0.086 | E24: 502 | F24: 0.26 | G24: 4 | H24: 2 | I24: All
B25: G36C | C25: 43 | D25: 0.086 | E25: 502 | F25: 0.26 | G25: 4 | H25: 2 | I25: Vikendi Only
B26: QBZ 95 | C26: 43 | D26: 0.092 | E26: 466 | F26: 0.28 | G26: 4 | H26: 2 | I26: Sanhok Only
B27: Scar-L | C27: 43 | D27: 0.096 | E27: 448 | F27: 0.29 | G27: 4 | H27: 2 | I27: Erangel / Miramar
B28: VSS | C28: 41 | D28: 0.086 | E28: 479 | F28: 0.26 | G28: 4 | H28: 2 | I28: All
B29: Tommy Gun | C29: 40 | D29: 0.086 | E29: 467 | F29: 0.34 | G29: 4 | H29: 3 | I29: All
B30: UMP9 | C30: 39 | D30: 0.092 | E30: 423 | F30: 0.37 | G30: 4 | H30: 3 | I30: All
B31: Vector | C31: 34 | D31: 0.055 | E31: 624 | F31: 0.22 | G31: 5 | H31: 3 | I31: All
B32: UZI | C32: 26 | D32: 0.048 | E32: 542 | F32: 0.29 | G32: 7 | H32: 4 | I32: All

Sheet dirlist
B1: chlamydia gonorrhea test | C1: =PROPER(B1) -> Chlamydia Gonorrhea Test
B2: chlamydia risks complications | C2: =PROPER(B2) -> Chlamydia Risks Complications
B3: chlamydia symptoms | C3: =PROPER(B3) -> Chlamydia Symptoms
B4: chlamydia test | C4: =PROPER(B4) -> Chlamydia Test
B5: chlamydia testing | C5: =PROPER(B5) -> Chlamydia Testing
B6: chlamydia treatment | C6: =PROPER(B6) -> Chlamydia Treatment
B7: confidential std testing | C7: =PROPER(B7) -> Confidential Std Testing
B8: connecticut std testing | C8: =PROPER(B8) -> Connecticut Std Testing
B9: delaware std testing | C9: =PROPER(B9) -> Delaware Std Testing
B10: gonorrhea risks complications | C10: =PROPER(B10) -> Gonorrhea Risks Complications
B11: gonorrhea symptoms | C11: =PROPER(B11) -> Gonorrhea Symptoms
B12: gonorrhea test | C12: =PROPER(B12) -> Gonorrhea Test
... B79: syphilis | C79: =PROPER(B79) -> Syphilis

Sheet Sheet1
A1: Big Sister 1/ Email Address | B1: PassWord | C1: Computer Name | D1: Info:
A3: deadman315@hotmail.com | B3: robvandam315 | C3: Stix
A5: alec_vasileiadis@hotmail.com | B5: greece
A7: tammydah@hotmail.com | B7: wilsonton | C7: dahler
A9: wrx_000@hotmail.com | B9: toowoomba | C9: dahler
A11: pingustix@hotmail.com | B11: fastplant | C11: Stix
A13: psycoclown201@hotmail.com | B13: fastplant | C13: Stix
A15: adrielchen0509@yahoo.com | B15: godisking | C15: Schaefen
E16: PROJECT MADE BY SPYBOY ALL WAS DONE BY MYSELF
A17: dextdog@hotmail.com | B17: dexter | C17: harmerant
A19: nickchan91@hotmail.com | B19: isiah34
A20: kiwirulz_7811@hotmail.com | B20: fucklife | C20: nicola
A21: shahidkhan570@hotmail.com | B21: pioneer | C21: PC1
A23: h_v_mittal@hotmail.com | B23: instrument | C23: Adminstrator
A25: dubbls@hotmail.com | B25: linronda/kingston | C25: Dubbls | E25: Taken Over
A27: priya4uin@hotmail.com | B27: iloveu | C27: Mach-1
A29: primrose_lust@hotmail.com | B29: jennarayjohnston | C29: owner
A31: danny_wedge@hotmail.com | B31: THEREDS | C31: MarkWhale
A33: htegg1@hotmail.com | B33: katiedog | C33: Ian Tegg
A35: Yahoo! Games | B35: g2lgratton[TAB]825564 | C35: Laura
B37: jonothan | C37: jacqueline McAulay
A39: abed_200@hotmail.com | B39: 3l1t34b3d@hell | C39: NoName
A41: gv_of_e@hotmail.com | B41: blackadder | C41: julia vince
A43: vinnie461@hotmail.com | B43: 461739 | C43: julia vince
A45: police_17@hotmail.com | B45: choclate | C45: pc1
A47: ady@hehe.com | B47: choclate | C47: pc1
A49: waqas_ahmed16@hotmail.com | B49: wicky111 | C49: pc1
A51: yasirbutt786@hotmail.com | B51: 2575036 | C51: pc1
A53: ali_akber_jamali@hotmail.com | B53: sakina | C53: pc1
A55: aliabbaz690@hotmail.com | B55: 6624109 | C55: pc1
A57: admirable_gal@hotmail.com | B57: sillyfiz | C57: pc1
A59: ando20000@hotmail.com | B59: 124643246
A61: sexy_lil_thingy_@hotmail.com | B61: whatupthefuckers
A63: mariokart_2002@hotmail.com | B63: 1471236 | C63: Neil
A65: backermalaker@hotmail.com | B65: arsepower | C65: Ian Baker
A67: murtaza_batman@hotmail.com | B67: tummytruck309 | C67: Murtaza Yousuf Ali
A69: rashida1985@hotmail.com | B69: batool_mufi | C69: Murtaza Yousuf Ali
A71: vinnie461@hotmail.com | B71: 461739 | C71: julia vince
A73: sexy_lil_thingy_@hotmail.com | B73: whatupthefuckers | C73: default
A75: alienization@hotmail.com | B75: motherfucker17 | C75: NoName
...

Sheet Sheet4
G5: SÍFILIS | I5: =PROPER(G5) -> Sífilis
I6: =PROPER(G6)
G7: VIRUS HEPATÍTIS B | I7: =PROPER(G7) -> Virus Hepatítis B
I8: =PROPER(G8)
G9: HERPES | I9: =PROPER(G9) -> Herpes
I10: =PROPER(G10)
G11: GONORREA | I11: =PROPER(G11) -> Gonorrea
I12: =PROPER(G12)
G13: CLAMIDIA | I13: =PROPER(G13) -> Clamidia
G14: MYCOPLASMA / UREAPLASMA | I14: =PROPER(G14) -> Mycoplasma / Ureaplasma
I15: =PROPER(G15)
G16: PAPILOMA HUMANO | I16: =PROPER(G16) -> Papiloma Humano
I17: =PROPER(G17)
G18: GONORREA | I18: =PROPER(G18) -> Gonorrea
I19: =PROPER(G19)
G20: VIH (VIRUS DE INMUNODEFICIENCA HUMANA) | I20: =PROPER(G20) -> Vih (Virus De Inmunodeficienca Humana)

Sheet Body Parts
K1: blank
A2: XML Meta Tags | K2: - | L2: =LEN(K2) -> 1
C3: Body Parts | D3: Wars Removal
C4: Cheek | D4: face | E4: warts | F4: removal | G4: .html | H4: <a href=" | I4: =CONCATENATE(D4,$K$2,E4,$K$2,F4,G4) -> face-warts-removal.html | J4: "> | K4: =PROPER(CONCATENATE(D4," ",E4," ",F4)) -> Face Warts Removal | L4: </a> | M4: =CONCATENATE(H4,I4,J4,K4,L4) -> <a href="face-warts-removal.html">Face Warts Removal</a>
C5: Chin | D5: neck | E5: warts | F5: removal | G5: .html | H5: <a href=" | I5: =CONCATENATE(D5,$K$2,E5,$K$2,F5,G5) -> neck-warts-removal.html | J5: "> | K5: =PROPER(CONCATENATE(D5," ",E5," ",F5)) -> Neck Warts Removal | L5: </a> | M5: =CONCATENATE(H5,I5,J5,K5,L5) -> <a href="neck-warts-removal.html">Neck Warts Removal</a>
C6: Neck | D6: shoulder | E6: warts | F6: removal | G6: .html | H6: <a href=" | I6: =CONCATENATE(D6,$K$2,E6,$K$2,F6,G6) -> shoulder-warts-removal.html | J6: "> | K6: =PROPER(CONCATENATE(D6," ",E6," ",F6)) -> Shoulder Warts Removal | L6: </a> | M6: =CONCATENATE(H6,I6,J6,K6,L6) -> <a href="shoulder-warts-removal.html">Shoulder Warts Removal</a>
A7: <head>mole removal</head> | C7: Shoulder | D7: breast | E7: warts | F7: removal | G7: .html | H7: <a href=" | I7: =CONCATENATE(D7,$K$2,E7,$K$2,F7,G7) -> breast-warts-removal.html | J7: "> | K7: =PROPER(CONCATENATE(D7," ",E7," ",F7)) -> Breast Warts Removal | L7: </a> | M7: =CONCATENATE(H7,I7,J7,K7,L7) -> <a href="breast-warts-removal.html">Breast Warts Removal</a>
A8: <company>Cosmocare Medical Center</company> | C8: Breast | D8: back | E8: warts | F8: removal | G8: .html | H8: <a href=" | I8: =CONCATENATE(D8,$K$2,E8,$K$2,F8,G8) -> back-warts-removal.html | J8: "> | K8: =PROPER(CONCATENATE(D8," ",E8," ",F8)) -> Back Warts Removal | L8: </a> | M8: =CONCATENATE(H8,I8,J8,K8,L8) -> <a href="back-warts-removal.html">Back Warts Removal</a>
A9: <phone>04 379 8747</phone> | C9: Navel | D9: hand | E9: warts | F9: removal | G9: .html | H9: <a href=" | I9: =CONCATENATE(D9,$K$2,E9,$K$2,F9,G9) -> hand-warts-removal.html | J9: "> | K9: =PROPER(CONCATENATE(D9," ",E9," ",F9)) -> Hand Warts Removal | L9: </a> | M9: =CONCATENATE(H9,I9,J9,K9,L9) -> <a href="hand-warts-removal.html">Hand Warts Removal</a>
A10: <region name="Asia"> | C10: Abdomen | D10: buttock | E10: warts | F10: removal | G10: .html | H10: <a href=" | I10: =CONCATENATE(D10,$K$2,E10,$K$2,F10,G10) -> buttock-warts-removal.html | J10: "> | K10: =PROPER(CONCATENATE(D10," ",E10," ",F10)) -> Buttock Warts Removal | L10: </a> | M10: =CONCATENATE(H10,I10,J10,K10,L10) -> <a href="buttock-warts-removal.html">Buttock Warts Removal</a>
A11: <country name="United Arab Emirates"> | C11: Neck | D11: thigh | E11: warts | F11: removal | G11: .html | H11: <a href=" | I11: =CONCATENATE(D11,$K$2,E11,$K$2,F11,G11) -> thigh-warts-removal.html | J11: "> | K11: =PROPER(CONCATENATE(D11," ",E11," ",F11)) -> Thigh Warts Removal | L11: </a> | M11: =CONCATENATE(H11,I11,J11,K11,L11) -> <a href="thigh-warts-removal.html">Thigh Warts Removal</a>
A12: <city>Dubai</city> | C12: Shoulder Blade
A13: </country> | C13: Arm
A14: </region> | C14: Elbow
C15: Back
C16: Hand
C17: Buttock
C18: Thigh
D23: =SUM(D24:D40) -> 45 | E23: =SUM(E24:E40) -> 54
D24: 1 | E24: 3
D25: 2 | E25: 3
D26: 3 | E26: 3
D27: 4 | E27: 6
D28: 5 | E28: 6
D29: 6 | E29: 6
D30: 7 | E30: 9
D31: 8 | E31: 9
D32: 9 | E32: 9

Sheet mughal steel works
K1: blank
A2: XML Meta Tags | K2: - | L2: =LEN(K2) -> 1
C3: Body Parts | D3: Iron Welding Works
C4: iron | D4: Iron | E4: Sliding | F4: Gate | H4: <a href="works.php?welding= | I4: =CONCATENATE(D4,$K$2,E4,$K$2,F4,G4) -> Iron-Sliding-Gate | J4: "> | K4: =PROPER(CONCATENATE(D4," ",E4," ",F4)) -> Iron Sliding Gate | L4: </a> <br /> | M4: =CONCATENATE(H4,I4,J4,K4,L4) -> <a href="works.php?welding=Iron-Sliding-Gate">Iron Sliding Gate</a> <br />
D5: Iron | E5: Sliding | F5: Windows | H5: <a href="works.php?welding= | I5: =CONCATENATE(D5,$K$2,E5,$K$2,F5,G5) -> Iron-Sliding-Windows | J5: "> | K5: =PROPER(CONCATENATE(D5," ",E5," ",F5)) -> Iron Sliding Windows | L5: </a> <br /> | M5: =CONCATENATE(H5,I5,J5,K5,L5) -> <a href="works.php?welding=Iron-Sliding-Windows">Iron Sliding Windows</a> <br />
D6: Iron | E6: Kids | F6: Slide | H6: <a href="works.php?welding= | I6: =CONCATENATE(D6,$K$2,E6,$K$2,F6,G6) -> Iron-Kids-Slide | J6: "> | K6: =PROPER(CONCATENATE(D6," ",E6," ",F6)) -> Iron Kids Slide | L6: </a> <br /> | M6: =CONCATENATE(H6,I6,J6,K6,L6) -> <a href="works.php?welding=Iron-Kids-Slide">Iron Kids Slide</a> <br />
A7: <head>mole removal</head> | D7: Iron | E7: Swing | F7: Cradle | H7: <a href="works.php?welding= | I7: =CONCATENATE(D7,$K$2,E7,$K$2,F7,G7) -> Iron-Swing-Cradle | J7: "> | K7: =PROPER(CONCATENATE(D7," ",E7," ",F7)) -> Iron Swing Cradle | L7: </a> <br /> | M7: =CONCATENATE(H7,I7,J7,K7,L7) -> <a href="works.php?welding=Iron-Swing-Cradle">Iron Swing Cradle</a> <br />
A8: <company>Cosmocare Medical Center</company> | D8: Iron | E8: Tables | F8: Welding | H8: <a href="works.php?welding= | I8: =CONCATENATE(D8,$K$2,E8,$K$2,F8,G8) -> Iron-Tables-Welding | J8: "> | K8: =PROPER(CONCATENATE(D8," ",E8," ",F8)) -> Iron Tables Welding | L8: </a> <br /> | M8: =CONCATENATE(H8,I8,J8,K8,L8) -> <a href="works.php?welding=Iron-Tables-Welding">Iron Tables Welding</a> <br />
A9: <phone>04 379 8747</phone> | D9: Iron | E9: Stool | F9: Welding | H9: <a href="works.php?welding= | I9: =CONCATENATE(D9,$K$2,E9,$K$2,F9,G9) -> Iron-Stool-Welding | J9: "> | K9: =PROPER(CONCATENATE(D9," ",E9," ",F9)) -> Iron Stool Welding | L9: </a> <br /> | M9: =CONCATENATE(H9,I9,J9,K9,L9) -> <a href="works.php?welding=Iron-Stool-Welding">Iron Stool Welding</a> <br />
A10: <region name="Asia"> | D10: Iron | E10: Chairs | F10: Welding | H10: <a href="works.php?welding= | I10: =CONCATENATE(D10,$K$2,E10,$K$2,F10,G10) -> Iron-Chairs-Welding | J10: "> | K10: =PROPER(CONCATENATE(D10," ",E10," ",F10)) -> Iron Chairs Welding | L10: </a> <br /> | M10: =CONCATENATE(H10,I10,J10,K10,L10) -> <a href="works.php?welding=Iron-Chairs-Welding">Iron Chairs Welding</a> <br />
A11: <country name="United Arab Emirates"> | D11: Iron | E11: Steps | F11: Welding | H11: <a href="works.php?welding= | I11: =CONCATENATE(D11,$K$2,E11,$K$2,F11,G11) -> Iron-Steps-Welding | J11: "> | K11: =PROPER(CONCATENATE(D11," ",E11," ",F11)) -> Iron Steps Welding | L11: </a> <br /> | M11: =CONCATENATE(H11,I11,J11,K11,L11) -> <a href="works.php?welding=Iron-Steps-Welding">Iron Steps Welding</a> <br />
A12: <city>Dubai</city> | D12: Iron | E12: Racks | F12: Welding | H12: <a href="works.php?welding= | I12: =CONCATENATE(D12,$K$2,E12,$K$2,F12,G12) -> Iron-Racks-Welding | J12: "> | K12: =PROPER(CONCATENATE(D12," ",E12," ",F12)) -> Iron Racks Welding | L12: </a> <br /> | M12: =CONCATENATE(H12,I12,J12,K12,L12) -> <a href="works.php?welding=Iron-Racks-Welding">Iron Racks Welding</a> <br />
A13: </country> | D13: Iron | E13: Gate | F13: Welding | H13: <a href="works.php?welding= | I13: =CONCATENATE(D13,$K$2,E13,$K$2,F13,G13) -> Iron-Gate-Welding | J13: "> | K13: =PROPER(CONCATENATE(D13," ",E13," ",F13)) -> Iron Gate Welding | L13: </a> <br /> | M13: =CONCATENATE(H13,I13,J13,K13,L13) -> <a href="works.php?welding=Iron-Gate-Welding">Iron Gate Welding</a> <br />
A14: </region> | D14: Iron | E14: Windows | F14: Welding | H14: <a href="works.php?welding= | I14: =CONCATENATE(D14,$K$2,E14,$K$2,F14,G14) -> Iron-Windows-Welding | J14: "> | K14: =PROPER(CONCATENATE(D14," ",E14," ",F14)) -> Iron Windows Welding | L14: </a> <br /> | M14: =CONCATENATE(H14,I14,J14,K14,L14) -> <a href="works.php?welding=Iron-Windows-Welding">Iron Windows Welding</a> <br />
D15: Iron | E15: Grills | F15: Welding | H15: <a href="works.php?welding= | I15: =CONCATENATE(D15,$K$2,E15,$K$2,F15,G15) -> Iron-Grills-Welding | J15: "> | K15: =PROPER(CONCATENATE(D15," ",E15," ",F15)) -> Iron Grills Welding | L15: </a> <br /> | M15: =CONCATENATE(H15,I15,J15,K15,L15) -> <a href="works.php?welding=Iron-Grills-Welding">Iron Grills Welding</a> <br />
D16: Iron | E16: Stairs | F16: Welding | H16: <a href="works.php?welding= | I16: =CONCATENATE(D16,$K$2,E16,$K$2,F16,G16) -> Iron-Stairs-Welding | J16: "> | K16: =PROPER(CONCATENATE(D16," ",E16," ",F16)) -> Iron Stairs Welding | L16: </a> <br /> | M16: =CONCATENATE(H16,I16,J16,K16,L16) -> <a href="works.php?welding=Iron-Stairs-Welding">Iron Stairs Welding</a> <br />
D17: Iron | E17: Door | F17: Welding | H17: <a href="works.php?welding= | I17: =CONCATENATE(D17,$K$2,E17,$K$2,F17,G17) -> Iron-Door-Welding | J17: "> | K17: =PROPER(CONCATENATE(D17," ",E17," ",F17)) -> Iron Door Welding | L17: </a> <br /> | M17: =CONCATENATE(H17,I17,J17,K17,L17) -> <a href="works.php?welding=Iron-Door-Welding">Iron Door Welding</a> <br />
D18: Iron | E18: Fences | F18: Welding | H18: <a href="works.php?welding= | I18: =CONCATENATE(D18,$K$2,E18,$K$2,F18,G18) -> Iron-Fences-Welding | J18: "> | K18: =PROPER(CONCATENATE(D18," ",E18," ",F18)) -> Iron Fences Welding | L18: </a> <br /> | M18: =CONCATENATE(H18,I18,J18,K18,L18) -> <a href="works.php?welding=Iron-Fences-Welding">Iron Fences Welding</a> <br />
D19: Iron | E19: Furniture | F19: Welding | H19: <a href="works.php?welding= | I19: =CONCATENATE(D19,$K$2,E19,$K$2,F19,G19) -> Iron-Furniture-Welding | J19: "> | K19: =PROPER(CONCATENATE(D19," ",E19," ",F19)) -> Iron Furniture Welding | L19: </a> <br /> | M19: =CONCATENATE(H19,I19,J19,K19,L19) -> <a href="works.php?welding=Iron-Furniture-Welding">Iron Furniture Welding</a> <br />
D20: Iron | E20: Railings | F20: Welding | H20: <a href="works.php?welding= | I20: =CONCATENATE(D20,$K$2,E20,$K$2,F20,G20) -> Iron-Railings-Welding | J20: "> | K20: =PROPER(CONCATENATE(D20," ",E20," ",F20)) -> Iron Railings Welding | L20: </a> <br /> | M20: =CONCATENATE(H20,I20,J20,K20,L20) -> <a href="works.php?welding=Iron-Railings-Welding">Iron Railings Welding</a> <br />
D21: Iron | E21: Chokhat | F21: Welding | H21: <a href="works.php?welding= | I21: =CONCATENATE(D21,$K$2,E21,$K$2,F21,G21) -> Iron-Chokhat-Welding | J21: "> | K21: =PROPER(CONCATENATE(D21," ",E21," ",F21)) -> Iron Chokhat Welding | L21: </a> <br /> | M21: =CONCATENATE(H21,I21,J21,K21,L21) -> <a href="works.php?welding=Iron-Chokhat-Welding">Iron Chokhat Welding</a> <br />
D22: Folding | E22: Gate | F22: Welding | H22: <a href="works.php?welding= | I22: =CONCATENATE(D22,$K$2,E22,$K$2,F22,G22) -> Folding-Gate-Welding | J22: "> | K22: =PROPER(CONCATENATE(D22," ",E22," ",F22)) -> Folding Gate Welding | L22: </a> <br /> | M22: =CONCATENATE(H22,I22,J22,K22,L22) -> <a href="works.php?welding=Folding-Gate-Welding">Folding Gate Welding</a> <br />
D23: Shutter | E23: Gate | F23: Welding | H23: <a href="works.php?welding= | I23: =CONCATENATE(D23,$K$2,E23,$K$2,F23,G23) -> Shutter-Gate-Welding | J23: "> | K23: =PROPER(CONCATENATE(D23," ",E23," ",F23)) -> Shutter Gate Welding | L23: </a> <br /> | M23: =CONCATENATE(H23,I23,J23,K23,L23) -> <a href="works.php?welding=Shutter-Gate-Welding">Shutter Gate Welding</a> <br />
D24: Round | E24: Stairs | F24: Welding | H24: <a href="works.php?welding= | I24: =CONCATENATE(D24,$K$2,E24,$K$2,F24,G24) -> Round-Stairs-Welding | J24: "> | K24: =PROPER(CONCATENATE(D24," ",E24," ",F24)) -> Round Stairs Welding | L24: </a> <br /> | M24: =CONCATENATE(H24,I24,J24,K24,L24) -> <a href="works.php?welding=Round-Stairs-Welding">Round Stairs Welding</a> <br />
D25: Steel | E25: Gate | F25: Welding | H25: <a href="works.php?welding= | I25: =CONCATENATE(D25,$K$2,E25,$K$2,F25,G25) -> Steel-Gate-Welding | J25: "> | K25: =PROPER(CONCATENATE(D25," ",E25," ",F25)) -> Steel Gate Welding | L25: </a> <br /> | M25: =CONCATENATE(H25,I25,J25,K25,L25) -> <a href="works.php?welding=Steel-Gate-Welding">Steel Gate Welding</a> <br />
D26: Steel | E26: Windows | F26: Welding | H26: <a href="works.php?welding= | I26: =CONCATENATE(D26,$K$2,E26,$K$2,F26,G26) -> Steel-Windows-Welding | J26: "> | K26: =PROPER(CONCATENATE(D26," ",E26," ",F26)) -> Steel Windows Welding | L26: </a> <br /> | M26: =CONCATENATE(H26,I26,J26,K26,L26) -> <a href="works.php?welding=Steel-Windows-Welding">Steel Windows Welding</a> <br />
... D74: Rod | E74: Iron | F74: Bed | H74: <a href="works.php?welding= | I74: =CONCATENATE(D74,$K$2,E74,$K$2,F74,G74) -> Rod-Iron-Bed | J74: "> | K74: =PROPER(CONCATENATE(D74," ",E74," ",F74)) -> Rod Iron Bed | L74: </a> <br /> | M74: =CONCATENATE(H74,I74,J74,K74,L74) -> <a href="works.php?welding=Rod-Iron-Bed">Rod Iron Bed</a> <br />

Sheet mughal steel works (2)
I1: .html | K1: blank
A2: XML Meta Tags | K2: - | L2: =LEN(K2) -> 1
C3: Body Parts | D3: Iron Welding Works
C4: iron | D4: Iron | E4: Sliding | F4: Gate | H4: <a href="work/ | I4: =CONCATENATE(D4,$K$2,E4,$K$2,F4,G4,$I$1) -> Iron-Sliding-Gate.html | J4: " target="_blank"> | K4: =PROPER(CONCATENATE(D4," ",E4," ",F4)) -> Iron Sliding Gate | L4: </a> <br /> | M4: =CONCATENATE(H4,I4,J4,K4,L4) -> <a href="work/Iron-Sliding-Gate.html" target="_blank">Iron Sliding Gate</a> <br />
D5: Iron | E5: Sliding | F5: Windows | H5: <a href="work/ | I5: =CONCATENATE(D5,$K$2,E5,$K$2,F5,G5,$I$1) -> Iron-Sliding-Windows.html | J5: " target="_blank"> | K5: =PROPER(CONCATENATE(D5," ",E5," ",F5)) -> Iron Sliding Windows | L5: </a> <br /> | M5: =CONCATENATE(H5,I5,J5,K5,L5) -> <a href="work/Iron-Sliding-Windows.html" target="_blank">Iron Sliding Windows</a> <br />
D6: Iron | E6: Kids | F6: Slide | H6: <a href="work/ | I6: =CONCATENATE(D6,$K$2,E6,$K$2,F6,G6,$I$1) -> Iron-Kids-Slide.html | J6: " target="_blank"> | K6: =PROPER(CONCATENATE(D6," ",E6," ",F6)) -> Iron Kids Slide | L6: </a> <br /> | M6: =CONCATENATE(H6,I6,J6,K6,L6) -> <a href="work/Iron-Kids-Slide.html" target="_blank">Iron Kids Slide</a> <br />
A7: <head>mole removal</head> | D7: Iron | E7: Swing | F7: Cradle | H7: <a href="work/ | I7: =CONCATENATE(D7,$K$2,E7,$K$2,F7,G7,$I$1) -> Iron-Swing-Cradle.html | J7: " target="_blank"> | K7: =PROPER(CONCATENATE(D7," ",E7," ",F7)) -> Iron Swing Cradle | L7: </a> <br /> | M7: =CONCATENATE(H7,I7,J7,K7,L7) -> <a href="work/Iron-Swing-Cradle.html" target="_blank">Iron Swing Cradle</a> <br />
A8: <company>Cosmocare Medical Center</company> | D8: Iron | E8: Tables | F8: Welding | H8: <a href="work/ | I8: =CONCATENATE(D8,$K$2,E8,$K$2,F8,G8,$I$1) -> Iron-Tables-Welding.html | J8: " target="_blank"> | K8: =PROPER(CONCATENATE(D8," ",E8," ",F8)) -> Iron Tables Welding | L8: </a> <br /> | M8: =CONCATENATE(H8,I8,J8,K8,L8) -> <a href="work/Iron-Tables-Welding.html" target="_blank">Iron Tables Welding</a> <br />
A9: <phone>04 379 8747</phone> | D9: Iron | E9: Stool | F9: Welding | H9: <a href="work/ | I9: =CONCATENATE(D9,$K$2,E9,$K$2,F9,G9,$I$1) -> Iron-Stool-Welding.html | J9: " target="_blank"> | K9: =PROPER(CONCATENATE(D9," ",E9," ",F9)) -> Iron Stool Welding | L9: </a> <br /> | M9: =CONCATENATE(H9,I9,J9,K9,L9) -> <a href="work/Iron-Stool-Welding.html" target="_blank">Iron Stool Welding</a> <br />
A10: <region name="Asia"> | D10: Iron | E10: Chairs | F10: Welding | H10: <a href="work/ | I10: =CONCATENATE(D10,$K$2,E10,$K$2,F10,G10,$I$1) -> Iron-Chairs-Welding.html | J10: " target="_blank"> | K10: =PROPER(CONCATENATE(D10," ",E10," ",F10)) -> Iron Chairs Welding | L10: </a> <br /> | M10: =CONCATENATE(H10,I10,J10,K10,L10) -> <a href="work/Iron-Chairs-Welding.html" target="_blank">Iron Chairs Welding</a> <br />
A11: <country name="United Arab Emirates"> | D11: Iron | E11: Steps | F11: Welding | H11: <a href="work/ | I11: =CONCATENATE(D11,$K$2,E11,$K$2,F11,G11,$I$1) -> Iron-Steps-Welding.html | J11: " target="_blank"> | K11: =PROPER(CONCATENATE(D11," ",E11," ",F11)) -> Iron Steps Welding | L11: </a> <br /> | M11: =CONCATENATE(H11,I11,J11,K11,L11) -> <a href="work/Iron-Steps-Welding.html" target="_blank">Iron Steps Welding</a> <br />
A12: <city>Dubai</city> | D12: Iron | E12: Racks | F12: Welding | H12: <a href="work/ | I12: =CONCATENATE(D12,$K$2,E12,$K$2,F12,G12,$I$1) -> Iron-Racks-Welding.html | J12: " target="_blank"> | K12: =PROPER(CONCATENATE(D12," ",E12," ",F12)) -> Iron Racks Welding | L12: </a> <br /> | M12: =CONCATENATE(H12,I12,J12,K12,L12) -> <a href="work/Iron-Racks-Welding.html" target="_blank">Iron Racks Welding</a> <br />
A13: </country> | D13: Iron | E13: Gate | F13: Welding | H13: <a href="work/ | I13: =CONCATENATE(D13,$K$2,E13,$K$2,F13,G13,$I$1) -> Iron-Gate-Welding.html | J13: " target="_blank"> | K13: =PROPER(CONCATENATE(D13," ",E13," ",F13)) -> Iron Gate Welding | L13: </a> <br /> | M13: =CONCATENATE(H13,I13,J13,K13,L13) -> <a href="work/Iron-Gate-Welding.html" target="_blank">Iron Gate Welding</a> <br />
A14: </region> | D14: Iron | E14: Windows | F14: Welding | H14: <a href="work/ | I14: =CONCATENATE(D14,$K$2,E14,$K$2,F14,G14,$I$1) -> Iron-Windows-Welding.html | J14: " target="_blank"> | K14: =PROPER(CONCATENATE(D14," ",E14," ",F14)) -> Iron Windows Welding | L14: </a> <br /> | M14: =CONCATENATE(H14,I14,J14,K14,L14) -> <a href="work/Iron-Windows-Welding.html" target="_blank">Iron Windows Welding</a> <br />
D15: Iron | E15: Grills | F15: Welding | H15: <a href="work/ | I15: =CONCATENATE(D15,$K$2,E15,$K$2,F15,G15,$I$1) -> Iron-Grills-Welding.html | J15: " target="_blank"> | K15: =PROPER(CONCATENATE(D15," ",E15," ",F15)) -> Iron Grills Welding | L15: </a> <br /> | M15: =CONCATENATE(H15,I15,J15,K15,L15) -> <a href="work/Iron-Grills-Welding.html" target="_blank">Iron Grills Welding</a> <br />
D16: Iron | E16: Stairs | F16: Welding | H16: <a href="work/ | I16: =CONCATENATE(D16,$K$2,E16,$K$2,F16,G16,$I$1) -> Iron-Stairs-Welding.html | J16: " target="_blank"> | K16: =PROPER(CONCATENATE(D16," ",E16," ",F16)) -> Iron Stairs Welding | L16: </a> <br /> | M16: =CONCATENATE(H16,I16,J16,K16,L16) -> <a href="work/Iron-Stairs-Welding.html" target="_blank">Iron Stairs Welding</a> <br />
D17: Iron | E17: Door | F17: Welding | H17: <a href="work/ | I17: =CONCATENATE(D17,$K$2,E17,$K$2,F17,G17,$I$1) -> Iron-Door-Welding.html | J17: " target="_blank"> | K17: =PROPER(CONCATENATE(D17," ",E17," ",F17)) -> Iron Door Welding | L17: </a> <br /> | M17: =CONCATENATE(H17,I17,J17,K17,L17) -> <a href="work/Iron-Door-Welding.html" target="_blank">Iron Door Welding</a> <br />
D18: Iron | E18: Fences | F18: Welding | H18: <a href="work/ | I18: =CONCATENATE(D18,$K$2,E18,$K$2,F18,G18,$I$1) -> Iron-Fences-Welding.html | J18: " target="_blank"> | K18: =PROPER(CONCATENATE(D18," ",E18," ",F18)) -> Iron Fences Welding | L18: </a> <br /> | M18: =CONCATENATE(H18,I18,J18,K18,L18) -> <a href="work/Iron-Fences-Welding.html" target="_blank">Iron Fences Welding</a> <br />
D19: Iron | E19: Furniture | F19: Welding | H19: <a href="work/ | I19: =CONCATENATE(D19,$K$2,E19,$K$2,F19,G19,$I$1) -> Iron-Furniture-Welding.html | J19: " target="_blank"> | K19: =PROPER(CONCATENATE(D19," ",E19," ",F19)) -> Iron Furniture Welding | L19: </a> <br /> | M19: =CONCATENATE(H19,I19,J19,K19,L19) -> <a href="work/Iron-Furniture-Welding.html" target="_blank">Iron Furniture Welding</a> <br />
D20: Iron | E20: Railings | F20: Welding | H20: <a href="work/ | I20: =CONCATENATE(D20,$K$2,E20,$K$2,F20,G20,$I$1) -> Iron-Railings-Welding.html | J20: " target="_blank"> | K20: =PROPER(CONCATENATE(D20," ",E20," ",F20)) -> Iron Railings Welding | L20: </a> <br /> | M20: =CONCATENATE(H20,I20,J20,K20,L20) -> <a href="work/Iron-Railings-Welding.html" target="_blank">Iron Railings Welding</a> <br />
D21: Iron | E21: Chokhat | F21: Welding | H21: <a href="work/ | I21: =CONCATENATE(D21,$K$2,E21,$K$2,F21,G21,$I$1) -> Iron-Chokhat-Welding.html | J21: " target="_blank"> | K21: =PROPER(CONCATENATE(D21," ",E21," ",F21)) -> Iron Chokhat Welding | L21: </a> <br /> | M21: =CONCATENATE(H21,I21,J21,K21,L21) -> <a href="work/Iron-Chokhat-Welding.html" target="_blank">Iron Chokhat Welding</a> <br />
D22: Folding | E22: Gate | F22: Welding | H22: <a href="work/ | I22: =CONCATENATE(D22,$K$2,E22,$K$2,F22,G22,$I$1) -> Folding-Gate-Welding.html | J22: " target="_blank"> | K22: =PROPER(CONCATENATE(D22," ",E22," ",F22)) -> Folding Gate Welding | L22: </a> <br /> | M22: =CONCATENATE(H22,I22,J22,K22,L22) -> <a href="work/Folding-Gate-Welding.html" target="_blank">Folding Gate Welding</a> <br />
D23: Shutter | E23: Gate | F23: Welding | H23: <a href="work/ | I23: =CONCATENATE(D23,$K$2,E23,$K$2,F23,G23,$I$1) -> Shutter-Gate-Welding.html | J23: " target="_blank"> | K23: =PROPER(CONCATENATE(D23," ",E23," ",F23)) -> Shutter Gate Welding | L23: </a> <br /> | M23: =CONCATENATE(H23,I23,J23,K23,L23) -> <a href="work/Shutter-Gate-Welding.html" target="_blank">Shutter Gate Welding</a> <br />
D24: Round | E24: Stairs | F24: Welding | H24: <a href="work/ | I24: =CONCATENATE(D24,$K$2,E24,$K$2,F24,G24,$I$1) -> Round-Stairs-Welding.html | J24: " target="_blank"> | K24: =PROPER(CONCATENATE(D24," ",E24," ",F24)) -> Round Stairs Welding | L24: </a> <br /> | M24: =CONCATENATE(H24,I24,J24,K24,L24) -> <a href="work/Round-Stairs-Welding.html" target="_blank">Round Stairs Welding</a> <br />
D25: Steel | E25: Gate | F25: Welding | H25: <a href="work/ | I25: =CONCATENATE(D25,$K$2,E25,$K$2,F25,G25,$I$1) -> Steel-Gate-Welding.html | J25: " target="_blank"> | K25: =PROPER(CONCATENATE(D25," ",E25," ",F25)) -> Steel Gate Welding | L25: </a> <br /> | M25: =CONCATENATE(H25,I25,J25,K25,L25) -> <a href="work/Steel-Gate-Welding.html" target="_blank">Steel Gate Welding</a> <br />
D26: Steel | E26: Windows | F26: Welding | H26: <a href="work/ | I26: =CONCATENATE(D26,$K$2,E26,$K$2,F26,G26,$I$1) -> Steel-Windows-Welding.html | J26: " target="_blank"> | K26: =PROPER(CONCATENATE(D26," ",E26," ",F26)) -> Steel Windows Welding | L26: </a> <br /> | M26: =CONCATENATE(H26,I26,J26,K26,L26) -> <a href="work/Steel-Windows-Welding.html" target="_blank">Steel Windows Welding</a> <br />
... D74: Rod | E74: Iron | F74: Bed | H74: <a href="work/ | I74: =CONCATENATE(D74,$K$2,E74,$K$2,F74,G74,$I$1) -> Rod-Iron-Bed.html | J74: " target="_blank"> | K74: =PROPER(CONCATENATE(D74," ",E74," ",F74)) -> Rod Iron Bed | L74: </a> <br /> | M74: =CONCATENATE(H74,I74,J74,K74,L74) -> <a href="work/Rod-Iron-Bed.html" target="_blank">Rod Iron Bed</a> <br />

Sheet Removal Moles
L1: blank
A2: XML Meta Tags | L2: - | M2: =LEN(L2) -> 1
C3: Body Parts | D3: Iron Welding Works
C4: Abdomen | D4: Mole | E4: Removal | F4: On | G4: Abdomen | I4: <a target="_blank" href="dubai.php?uae= | J4: =CONCATENATE(D4,$L$2,E4,$L$2,F4,$L$2,G4,H4) -> Mole-Removal-On-Abdomen | K4: "> | L4: =PROPER(CONCATENATE(D4," ",E4," ",F4," ",G4," ",H4)) -> Mole Removal On Abdomen | M4: </a> <br /> | N4: =CONCATENATE(I4,J4,K4,L4,M4) -> <a target="_blank" href="dubai.php?uae=Mole-Removal-On-Abdomen">Mole Removal On Abdomen </a> <br />
C5: Arm | D5: Mole | E5: Removal | F5: On | G5: Arm | I5: <a target="_blank" href="dubai.php?uae= | J5: =CONCATENATE(D5,$L$2,E5,$L$2,F5,$L$2,G5,H5) -> Mole-Removal-On-Arm | K5: "> | L5: =PROPER(CONCATENATE(D5," ",E5," ",F5," ",G5," ",H5)) -> Mole Removal On Arm | M5: </a> <br /> | N5: =CONCATENATE(I5,J5,K5,L5,M5) -> <a target="_blank" href="dubai.php?uae=Mole-Removal-On-Arm">Mole Removal On Arm </a> <br />
C6: Back | D6: Mole | E6: Removal | F6: On | G6: Armpit | I6: <a target="_blank" href="dubai.php?uae= | J6: =CONCATENATE(D6,$L$2,E6,$L$2,F6,$L$2,G6,H6) -> Mole-Removal-On-Armpit | K6: "> | L6: =PROPER(CONCATENATE(D6," ",E6," ",F6," ",G6," ",H6)) -> Mole Removal On Armpit | M6: </a> <br /> | N6: =CONCATENATE(I6,J6,K6,L6,M6) -> <a target="_blank" href="dubai.php?uae=Mole-Removal-On-Armpit">Mole Removal On Armpit </a> <br />
C7: Breast | D7: Mole | E7: Removal | F7: On | G7: Back | I7: <a target="_blank" href="dubai.php?uae= | J7: =CONCATENATE(D7,$L$2,E7,$L$2,F7,$L$2,G7,H7) -> Mole-Removal-On-Back | K7: "> | L7: =PROPER(CONCATENATE(D7," ",E7," ",F7," ",G7," ",H7)) -> Mole Removal On Back | M7: </a> <br /> | N7: =CONCATENATE(I7,J7,K7,L7,M7) -> <a target="_blank" href="dubai.php?uae=Mole-Removal-On-Back">Mole Removal On Back </a> <br />
C8: Buttock | D8: Mole | E8: Removal | F8: On | G8: Breast | I8: <a target="_blank" href="dubai.php?uae= | J8: =CONCATENATE(D8,$L$2,E8,$L$2,F8,$L$2,G8,H8) -> Mole-Removal-On-Breast | K8: "> | L8: =PROPER(CONCATENATE(D8," ",E8," ",F8," ",G8," ",H8)) -> Mole Removal On Breast | M8: </a> <br /> | N8: =CONCATENATE(I8,J8,K8,L8,M8) -> <a target="_blank" href="dubai.php?uae=Mole-Removal-On-Breast">Mole Removal On Breast </a> <br />
C9: Chest | D9: Mole | E9: Removal | F9: On | G9: Buttock | I9: <a target="_blank" href="dubai.php?uae= | J9: =CONCATENATE(D9,$L$2,E9,$L$2,F9,$L$2,G9,H9) -> Mole-Removal-On-Buttock | K9: "> | L9: =PROPER(CONCATENATE(D9," ",E9," ",F9," ",G9," ",H9)) -> Mole Removal On Buttock | M9: </a> <br /> | N9: =CONCATENATE(I9,J9,K9,L9,M9) -> <a target="_blank" href="dubai.php?uae=Mole-Removal-On-Buttock">Mole Removal On Buttock </a> <br />
C10: Cheek | D10: Mole | E10: Removal | F10: On | G10: Cheek | I10: <a target="_blank" href="dubai.php?uae= | J10: =CONCATENATE(D10,$L$2,E10,$L$2,F10,$L$2,G10,H10) -> Mole-Removal-On-Cheek | K10: "> | L10: =PROPER(CONCATENATE(D10," ",E10," ",F10," ",G10," ",H10)) -> Mole Removal On Cheek | M10: </a> <br /> | N10: =CONCATENATE(I10,J10,K10,L10,M10) -> <a target="_blank" href="dubai.php?uae=Mole-Removal-On-Cheek">Mole Removal On Cheek </a> <br />
C11: Chin | D11: Mole | E11: Removal | F11: On | G11: Chest | I11: <a target="_blank" href="dubai.php?uae= | J11: =CONCATENATE(D11,$L$2,E11,$L$2,F11,$L$2,G11,H11) -> Mole-Removal-On-Chest | K11: "> | L11: =PROPER(CONCATENATE(D11," ",E11," ",F11," ",G11," ",H11)) -> Mole Removal On Chest | M11: </a> <br /> | N11: =CONCATENATE(I11,J11,K11,L11,M11) -> <a target="_blank" href="dubai.php?uae=Mole-Removal-On-Chest">Mole Removal On Chest </a> <br />
C12: Elbow | D12: Mole | E12: Removal | F12: On | G12: Chin | I12: <a target="_blank" href="dubai.php?uae= | J12: =CONCATENATE(D12,$L$2,E12,$L$2,F12,$L$2,G12,H12) -> Mole-Removal-On-Chin | K12: "> | L12: =PROPER(CONCATENATE(D12," ",E12," ",F12," ",G12," ",H12)) -> Mole Removal On Chin | M12: </a> <br /> | N12: =CONCATENATE(I12,J12,K12,L12,M12) -> <a target="_blank" href="dubai.php?uae=Mole-Removal-On-Chin">Mole Removal On Chin </a> <br />
C13: Hand | D13: Mole | E13: Removal | F13: On | G13: Ear | I13: <a target="_blank" href="dubai.php?uae= | J13: =CONCATENATE(D13,$L$2,E13,$L$2,F13,$L$2,G13,H13) -> Mole-Removal-On-Ear | K13: "> | L13: =PROPER(CONCATENATE(D13," ",E13," ",F13," ",G13," ",H13)) -> Mole Removal On Ear | M13: </a> <br /> | N13: =CONCATENATE(I13,J13,K13,L13,M13) -> <a target="_blank" href="dubai.php?uae=Mole-Removal-On-Ear">Mole Removal On Ear </a> <br />
C14: Navel | D14: Mole | E14: Removal | F14: On | G14: Elbow | I14: <a target="_blank" href="dubai.php?uae= | J14: =CONCATENATE(D14,$L$2,E14,$L$2,F14,$L$2,G14,H14) -> Mole-Removal-On-Elbow | K14: "> | L14: =PROPER(CONCATENATE(D14," ",E14," ",F14," ",G14," ",H14)) -> Mole Removal On Elbow | M14: </a> <br /> | N14: =CONCATENATE(I14,J14,K14,L14,M14) -> <a target="_blank" href="dubai.php?uae=Mole-Removal-On-Elbow">Mole Removal On Elbow </a> <br />
C15: Neck | D15: Mole | E15: Removal | F15: On | G15: Eyebrow | I15: <a target="_blank" href="dubai.php?uae= | J15: =CONCATENATE(D15,$L$2,E15,$L$2,F15,$L$2,G15,H15) -> Mole-Removal-On-Eyebrow | K15: "> | L15: =PROPER(CONCATENATE(D15," ",E15," ",F15," ",G15," ",H15)) -> Mole Removal On Eyebrow | M15: </a> <br /> | N15: =CONCATENATE(I15,J15,K15,L15,M15) -> <a target="_blank" href="dubai.php?uae=Mole-Removal-On-Eyebrow">Mole Removal On Eyebrow </a> <br />
... C26: Hips | D26: Mole | E26: Removal | F26: On | G26: Thigh | I26: <a target="_blank" href="dubai.php?uae= | J26: =CONCATENATE(D26,$L$2,E26,$L$2,F26,$L$2,G26,H26) -> Mole-Removal-On-Thigh | K26: "> | L26: =PROPER(CONCATENATE(D26," ",E26," ",F26," ",G26," ",H26)) -> Mole Removal On Thigh | M26: </a> <br /> | N26: =CONCATENATE(I26,J26,K26,L26,M26) -> <a target="_blank" href="dubai.php?uae=Mole-Removal-On-Thigh">Mole Removal On Thigh </a> <br />
D27: Mole | E27: Treatment | F27: On | G27: Abdomen | I27: <a target="_blank" href="dubai.php?uae= | J27: =CONCATENATE(D27,$L$2,E27,$L$2,F27,$L$2,G27,H27) -> Mole-Treatment-On-Abdomen | K27: "> | L27: =PROPER(CONCATENATE(D27," ",E27," ",F27," ",G27," ",H27)) -> Mole Treatment On Abdomen | M27: </a> <br /> | N27: =CONCATENATE(I27,J27,K27,L27,M27) -> <a target="_blank" href="dubai.php?uae=Mole-Treatment-On-Abdomen">Mole Treatment On Abdomen </a> <br />
D28: Mole | E28: Treatment | F28: On | G28: Arm | I28: <a target="_blank" href="dubai.php?uae= | J28: =CONCATENATE(D28,$L$2,E28,$L$2,F28,$L$2,G28,H28) -> Mole-Treatment-On-Arm | K28: "> | L28: =PROPER(CONCATENATE(D28," ",E28," ",F28," ",G28," ",H28)) -> Mole Treatment On Arm | M28: </a> <br /> | N28: =CONCATENATE(I28,J28,K28,L28,M28) -> <a target="_blank" href="dubai.php?uae=Mole-Treatment-On-Arm">Mole Treatment On Arm </a> <br />
D29: Mole | E29: Treatment | F29: On | G29: Armpit | I29: <a target="_blank" href="dubai.php?uae= | J29: =CONCATENATE(D29,$L$2,E29,$L$2,F29,$L$2,G29,H29) -> Mole-Treatment-On-Armpit | K29: "> | L29: =PROPER(CONCATENATE(D29," ",E29," ",F29," ",G29," ",H29)) -> Mole Treatment On Armpit | M29: </a> <br /> | N29: =CONCATENATE(I29,J29,K29,L29,M29) -> <a target="_blank" href="dubai.php?uae=Mole-Treatment-On-Armpit">Mole Treatment On Armpit </a> <br />
D30: Mole | E30: Treatment | F30: On | G30: Back | I30: <a target="_blank" href="dubai.php?uae= | J30: =CONCATENATE(D30,$L$2,E30,$L$2,F30,$L$2,G30,H30) -> Mole-Treatment-On-Back | K30: "> | L30: =PROPER(CONCATENATE(D30," ",E30," ",F30," ",G30," ",H30)) -> Mole Treatment On Back | M30: </a> <br /> | N30: =CONCATENATE(I30,J30,K30,L30,M30) -> <a target="_blank" href="dubai.php?uae=Mole-Treatment-On-Back">Mole Treatment On Back </a> <br />
D31: Mole | E31: Treatment | F31: On | G31: Breast | I31: <a target="_blank" href="dubai.php?uae= | J31: =CONCATENATE(D31,$L$2,E31,$L$2,F31,$L$2,G31,H31) -> Mole-Treatment-On-Breast | K31: "> | L31: =PROPER(CONCATENATE(D31," ",E31," ",F31," ",G31," ",H31)) -> Mole Treatment On Breast | M31: </a> <br /> | N31: =CONCATENATE(I31,J31,K31,L31,M31) -> <a target="_blank" href="dubai.php?uae=Mole-Treatment-On-Breast">Mole Treatment On Breast </a> <br />
D32: Mole | E32: Treatment | F32: On | G32: Buttock | I32: <a target="_blank" href="dubai.php?uae= | J32: =CONCATENATE(D32,$L$2,E32,$L$2,F32,$L$2,G32,H32) -> Mole-Treatment-On-Buttock | K32: "> | L32: =PROPER(CONCATENATE(D32," ",E32," ",F32," ",G32," ",H32)) -> Mole Treatment On Buttock | M32: </a> <br /> | N32: =CONCATENATE(I32,J32,K32,L32,M32) -> <a target="_blank" href="dubai.php?uae=Mole-Treatment-On-Buttock">Mole Treatment On Buttock </a> <br />
D33: Mole | E33: Treatment | F33: On | G33: Cheek | I33: <a target="_blank" href="dubai.php?uae= | J33: =CONCATENATE(D33,$L$2,E33,$L$2,F33,$L$2,G33,H33) -> Mole-Treatment-On-Cheek | K33: "> | L33: =PROPER(CONCATENATE(D33," ",E33," ",F33," ",G33," ",H33)) -> Mole Treatment On Cheek | M33: </a> <br /> | N33: =CONCATENATE(I33,J33,K33,L33,M33) -> <a target="_blank" href="dubai.php?uae=Mole-Treatment-On-Cheek">Mole Treatment On Cheek </a> <br />
D34: Mole | E34: Treatment | F34: On | G34: Chest | I34: <a target="_blank" href="dubai.php?uae= | J34: =CONCATENATE(D34,$L$2,E34,$L$2,F34,$L$2,G34,H34) -> Mole-Treatment-On-Chest | K34: "> | L34: =PROPER(CONCATENATE(D34," ",E34," ",F34," ",G34," ",H34)) -> Mole Treatment On Chest | M34: </a> <br /> | N34: =CONCATENATE(I34,J34,K34,L34,M34) -> <a target="_blank" href="dubai.php?uae=Mole-Treatment-On-Chest">Mole Treatment On Chest </a> <br />
D35: Mole | E35: Treatment | F35: On | G35: Chin | I35: <a target="_blank" href="dubai.php?uae= | J35: =CONCATENATE(D35,$L$2,E35,$L$2,F35,$L$2,G35,H35) -> Mole-Treatment-On-Chin | K35: "> | L35: =PROPER(CONCATENATE(D35," ",E35," ",F35," ",G35," ",H35)) -> Mole Treatment On Chin | M35: </a> <br /> | N35: =CONCATENATE(I35,J35,K35,L35,M35) -> <a target="_blank" href="dubai.php?uae=Mole-Treatment-On-Chin">Mole Treatment On Chin </a> <br />
D36: Mole | E36: Treatment | F36: On | G36: Ear | I36: <a target="_blank" href="dubai.php?uae= | J36: =CONCATENATE(D36,$L$2,E36,$L$2,F36,$L$2,G36,H36) -> Mole-Treatment-On-Ear | K36: "> | L36: =PROPER(CONCATENATE(D36," ",E36," ",F36," ",G36," ",H36)) -> Mole Treatment On Ear | M36: </a> <br /> | N36: =CONCATENATE(I36,J36,K36,L36,M36) -> <a target="_blank" href="dubai.php?uae=Mole-Treatment-On-Ear">Mole Treatment On Ear </a> <br />
D37: Mole | E37: Treatment | F37: On | G37: Elbow | I37: <a target="_blank" href="dubai.php?uae= | J37: =CONCATENATE(D37,$L$2,E37,$L$2,F37,$L$2,G37,H37) -> Mole-Treatment-On-Elbow | K37: "> | L37: =PROPER(CONCATENATE(D37," ",E37," ",F37," ",G37," ",H37)) -> Mole Treatment On Elbow | M37: </a> <br /> | N37: =CONCATENATE(I37,J37,K37,L37,M37) -> <a target="_blank" href="dubai.php?uae=Mole-Treatment-On-Elbow">Mole Treatment On Elbow </a> <br />
D38: Mole | E38: Treatment | F38: On | G38: Eyebrow | I38: <a target="_blank" href="dubai.php?uae= | J38: =CONCATENATE(D38,$L$2,E38,$L$2,F38,$L$2,G38,H38) -> Mole-Treatment-On-Eyebrow | K38: "> | L38: =PROPER(CONCATENATE(D38," ",E38," ",F38," ",G38," ",H38)) -> Mole Treatment On Eyebrow | M38: </a> <br /> | N38: =CONCATENATE(I38,J38,K38,L38,M38) -> <a target="_blank" href="dubai.php?uae=Mole-Treatment-On-Eyebrow">Mole Treatment On Eyebrow </a> <br />
... D95: Thigh | E95: Laser | F95: Mole | G95: Treatment | I95: <a target="_blank" href="dubai.php?uae= | J95: =CONCATENATE(D95,$L$2,E95,$L$2,F95,$L$2,G95,H95) -> Thigh-Laser-Mole-Treatment | K95: "> | L95: =PROPER(CONCATENATE(D95," ",E95," ",F95," ",G95," ",H95)) -> Thigh Laser Mole Treatment | M95: </a> <br /> | N95: =CONCATENATE(I95,J95,K95,L95,M95) -> <a target="_blank" href="dubai.php?uae=Thigh-Laser-Mole-Treatment">Thigh Laser Mole Treatment </a> <br />

Sheet Removal Warts
L1: blank
A2: XML Meta Tags | L2: - | M2: =LEN(L2) -> 1
C3: Body Parts | D3: Iron Welding Works
C4: Abdomen | D4: Warts | E4: Removal | F4: On | G4: Abdomen | I4: <a target="_blank" href="dubai.php?uae= | J4: =CONCATENATE(D4,$L$2,E4,$L$2,F4,$L$2,G4,H4) -> Warts-Removal-On-Abdomen | K4: "> | L4: =PROPER(CONCATENATE(D4," ",E4," ",F4," ",G4," ",H4)) -> Warts Removal On Abdomen | M4: </a> <br /> | N4: =CONCATENATE(I4,J4,K4,L4,M4) -> <a target="_blank" href="dubai.php?uae=Warts-Removal-On-Abdomen">Warts Removal On Abdomen </a> <br />
C5: Arm | D5: Warts | E5: Removal | F5: On | G5: Arm | I5: <a target="_blank" href="dubai.php?uae= | J5: =CONCATENATE(D5,$L$2,E5,$L$2,F5,$L$2,G5,H5) -> Warts-Removal-On-Arm | K5: "> | L5: =PROPER(CONCATENATE(D5," ",E5," ",F5," ",G5," ",H5)) -> Warts Removal On Arm | M5: </a> <br /> | N5: =CONCATENATE(I5,J5,K5,L5,M5) -> <a target="_blank" href="dubai.php?uae=Warts-Removal-On-Arm">Warts Removal On Arm </a> <br />
C6: Back | D6: Warts | E6: Removal | F6: On | G6: Armpit | I6: <a target="_blank" href="dubai.php?uae= | J6: =CONCATENATE(D6,$L$2,E6,$L$2,F6,$L$2,G6,H6) -> Warts-Removal-On-Armpit | K6: "> | L6: =PROPER(CONCATENATE(D6," ",E6," ",F6," ",G6," ",H6)) -> Warts Removal On Armpit | M6: </a> <br /> | N6: =CONCATENATE(I6,J6,K6,L6,M6) -> <a target="_blank" href="dubai.php?uae=Warts-Removal-On-Armpit">Warts Removal On Armpit </a> <br />
C7: Breast | D7: Warts | E7: Removal | F7: On | G7: Back | I7: <a target="_blank" href="dubai.php?uae= | J7: =CONCATENATE(D7,$L$2,E7,$L$2,F7,$L$2,G7,H7) -> Warts-Removal-On-Back | K7: "> | L7: =PROPER(CONCATENATE(D7," ",E7," ",F7," ",G7," ",H7)) -> Warts Removal On Back | M7: </a> <br /> | N7: =CONCATENATE(I7,J7,K7,L7,M7) -> <a target="_blank" href="dubai.php?uae=Warts-Removal-On-Back">Warts Removal On Back </a> <br />
C8: Buttock | D8: Warts | E8: Removal | F8: On | G8: Breast | I8: <a target="_blank" href="dubai.php?uae= | J8: =CONCATENATE(D8,$L$2,E8,$L$2,F8,$L$2,G8,H8) -> Warts-Removal-On-Breast | K8: "> | L8: =PROPER(CONCATENATE(D8," ",E8," ",F8," ",G8," ",H8)) -> Warts Removal On Breast | M8: </a> <br /> | N8: =CONCATENATE(I8,J8,K8,L8,M8) -> <a target="_blank" href="dubai.php?uae=Warts-Removal-On-Breast">Warts Removal On Breast </a> <br />
C9: Chest | D9: Warts | E9: Removal | F9: On | G9: Buttock | I9: <a target="_blank" href="dubai.php?uae= | J9: =CONCATENATE(D9,$L$2,E9,$L$2,F9,$L$2,G9,H9) -> Warts-Removal-On-Buttock | K9: "> | L9: =PROPER(CONCATENATE(D9," ",E9," ",F9," ",G9," ",H9)) -> Warts Removal On Buttock | M9: </a> <br /> | N9: =CONCATENATE(I9,J9,K9,L9,M9) -> <a target="_blank" href="dubai.php?uae=Warts-Removal-On-Buttock">Warts Removal On Buttock </a> <br />
C10: Cheek | D10: Warts | E10: Removal | F10: On | G10: Cheek | I10: <a target="_blank" href="dubai.php?uae= | J10: =CONCATENATE(D10,$L$2,E10,$L$2,F10,$L$2,G10,H10) -> Warts-Removal-On-Cheek | K10: "> | L10: =PROPER(CONCATENATE(D10," ",E10," ",F10," ",G10," ",H10)) -> Warts Removal On Cheek | M10: </a> <br /> | N10: =CONCATENATE(I10,J10,K10,L10,M10) -> <a target="_blank" href="dubai.php?uae=Warts-Removal-On-Cheek">Warts Removal On Cheek </a> <br />
C11: Chin | D11: Warts | E11: Removal | F11: On | G11: Chest | I11: <a target="_blank" href="dubai.php?uae= | J11: =CONCATENATE(D11,$L$2,E11,$L$2,F11,$L$2,G11,H11) -> Warts-Removal-On-Chest | K11: "> | L11: =PROPER(CONCATENATE(D11," ",E11," ",F11," ",G11," ",H11)) -> Warts Removal On Chest | M11: </a> <br /> | N11: =CONCATENATE(I11,J11,K11,L11,M11) -> <a target="_blank" href="dubai.php?uae=Warts-Removal-On-Chest">Warts Removal On Chest </a> <br />
C12: Elbow | D12: Warts | E12: Removal | F12: On | G12: Chin | I12: <a target="_blank" href="dubai.php?uae= | J12: =CONCATENATE(D12,$L$2,E12,$L$2,F12,$L$2,G12,H12) -> Warts-Removal-On-Chin | K12: "> | L12: =PROPER(CONCATENATE(D12," ",E12," ",F12," ",G12," ",H12)) -> Warts Removal On Chin | M12: </a> <br /> | N12: =CONCATENATE(I12,J12,K12,L12,M12) -> <a target="_blank" href="dubai.php?uae=Warts-Removal-On-Chin">Warts Removal On Chin </a> <br />
C13: Hand | D13: Warts | E13: Removal | F13: On | G13: Ear | I13: <a target="_blank" href="dubai.php?uae= | J13: =CONCATENATE(D13,$L$2,E13,$L$2,F13,$L$2,G13,H13) -> Warts-Removal-On-Ear | K13: "> | L13: =PROPER(CONCATENATE(D13," ",E13," ",F13," ",G13," ",H13)) -> Warts Removal On Ear | M13: </a> <br /> | N13: =CONCATENATE(I13,J13,K13,L13,M13) -> <a target="_blank" href="dubai.php?uae=Warts-Removal-On-Ear">Warts Removal On Ear </a> <br />
C14: Navel | D14: Warts | E14: Removal | F14: On | G14: Elbow | I14: <a target="_blank" href="dubai.php?uae= | J14: =CONCATENATE(D14,$L$2,E14,$L$2,F14,$L$2,G14,H14) -> Warts-Removal-On-Elbow | K14: "> | L14: =PROPER(CONCATENATE(D14," ",E14," ",F14," ",G14," ",H14)) -> Warts Removal On Elbow | M14: </a> <br /> | N14: =CONCATENATE(I14,J14,K14,L14,M14) -> <a target="_blank" href="dubai.php?uae=Warts-Removal-On-Elbow">Warts Removal On Elbow </a> <br />
C15: Neck | D15: Warts | E15: Removal | F15: On | G15: Eyebrow | I15: <a target="_blank" href="dubai.php?uae= | J15: =CONCATENATE(D15,$L$2,E15,$L$2,F15,$L$2,G15,H15) -> Warts-Removal-On-Eyebrow | K15: "> | L15: =PROPER(CONCATENATE(D15," ",E15," ",F15," ",G15," ",H15)) -> Warts Removal On Eyebrow | M15: </a> <br /> | N15: =CONCATENATE(I15,J15,K15,L15,M15) -> <a target="_blank" href="dubai.php?uae=Warts-Removal-On-Eyebrow">Warts Removal On Eyebrow </a> <br />
... C26: Hips | D26: Warts | E26: Removal | F26: On | G26: Thigh | I26: <a target="_blank" href="dubai.php?uae= | J26: =CONCATENATE(D26,$L$2,E26,$L$2,F26,$L$2,G26,H26) -> Warts-Removal-On-Thigh | K26: "> | L26: =PROPER(CONCATENATE(D26," ",E26," ",F26," ",G26," ",H26)) -> Warts Removal On Thigh | M26: </a> <br /> | N26: =CONCATENATE(I26,J26,K26,L26,M26) -> <a target="_blank" href="dubai.php?uae=Warts-Removal-On-Thigh">Warts Removal On Thigh </a> <br />
D27: Warts | E27: Treatment | F27: On | G27: Abdomen | I27: <a target="_blank" href="dubai.php?uae= | J27: =CONCATENATE(D27,$L$2,E27,$L$2,F27,$L$2,G27,H27) -> Warts-Treatment-On-Abdomen | K27: "> | L27: =PROPER(CONCATENATE(D27," ",E27," ",F27," ",G27," ",H27)) -> Warts Treatment On Abdomen | M27: </a> <br /> | N27: =CONCATENATE(I27,J27,K27,L27,M27) -> <a target="_blank" href="dubai.php?uae=Warts-Treatment-On-Abdomen">Warts Treatment On Abdomen </a> <br />
D28: Warts | E28: Treatment | F28: On | G28: Arm | I28: <a target="_blank" href="dubai.php?uae= | J28: =CONCATENATE(D28,$L$2,E28,$L$2,F28,$L$2,G28,H28) -> Warts-Treatment-On-Arm | K28: "> | L28: =PROPER(CONCATENATE(D28," ",E28," ",F28," ",G28," ",H28)) -> Warts Treatment On Arm | M28: </a> <br /> | N28: =CONCATENATE(I28,J28,K28,L28,M28) -> <a target="_blank" href="dubai.php?uae=Warts-Treatment-On-Arm">Warts Treatment On Arm </a> <br />
D29: Warts | E29: Treatment | F29: On | G29: Armpit | I29: <a target="_blank" href="dubai.php?uae= | J29: =CONCATENATE(D29,$L$2,E29,$L$2,F29,$L$2,G29,H29) -> Warts-Treatment-On-Armpit | K29: "> | L29: =PROPER(CONCATENATE(D29," ",E29," ",F29," ",G29," ",H29)) -> Warts Treatment On Armpit | M29: </a> <br /> | N29: =CONCATENATE(I29,J29,K29,L29,M29) -> <a target="_blank" href="dubai.php?uae=Warts-Treatment-On-Armpit">Warts Treatment On Armpit </a> <br />
D30: Warts | E30: Treatment | F30: On | G30: Back | I30: <a target="_blank" href="dubai.php?uae= | J30: =CONCATENATE(D30,$L$2,E30,$L$2,F30,$L$2,G30,H30) -> Warts-Treatment-On-Back | K30: "> | L30: =PROPER(CONCATENATE(D30," ",E30," ",F30," ",G30," ",H30)) -> Warts Treatment On Back | M30: </a> <br /> | N30: =CONCATENATE(I30,J30,K30,L30,M30) -> <a target="_blank" href="dubai.php?uae=Warts-Treatment-On-Back">Warts Treatment On Back </a> <br />
D31: Warts | E31: Treatment | F31: On | G31: Breast | I31: <a target="_blank" href="dubai.php?uae= | J31: =CONCATENATE(D31,$L$2,E31,$L$2,F31,$L$2,G31,H31) -> Warts-Treatment-On-Breast | K31: "> | L31: =PROPER(CONCATENATE(D31," ",E31," ",F31," ",G31," ",H31)) -> Warts Treatment On Breast | M31: </a> <br /> | N31: =CONCATENATE(I31,J31,K31,L31,M31) -> <a target="_blank" href="dubai.php?uae=Warts-Treatment-On-Breast">Warts Treatment On Breast </a> <br />
D32: Warts | E32: Treatment | F32: On | G32: Buttock | I32: <a target="_blank" href="dubai.php?uae= | J32: =CONCATENATE(D32,$L$2,E32,$L$2,F32,$L$2,G32,H32) -> Warts-Treatment-On-Buttock | K32: "> | L32: =PROPER(CONCATENATE(D32," ",E32," ",F32," ",G32," ",H32)) -> Warts Treatment On Buttock | M32: </a> <br /> | N32: =CONCATENATE(I32,J32,K32,L32,M32) -> <a target="_blank" href="dubai.php?uae=Warts-Treatment-On-Buttock">Warts Treatment On Buttock </a> <br />
D33: Warts | E33: Treatment | F33: On | G33: Cheek | I33: <a target="_blank" href="dubai.php?uae= | J33: =CONCATENATE(D33,$L$2,E33,$L$2,F33,$L$2,G33,H33) -> Warts-Treatment-On-Cheek | K33: "> | L33: =PROPER(CONCATENATE(D33," ",E33," ",F33," ",G33," ",H33)) -> Warts Treatment On Cheek | M33: </a> <br /> | N33: =CONCATENATE(I33,J33,K33,L33,M33) -> <a target="_blank" href="dubai.php?uae=Warts-Treatment-On-Cheek">Warts Treatment On Cheek </a> <br />
D34: Warts | E34: Treatment | F34: On | G34: Chest | I34: <a target="_blank" href="dubai.php?uae= | J34: =CONCATENATE(D34,$L$2,E34,$L$2,F34,$L$2,G34,H34) -> Warts-Treatment-On-Chest | K34: "> | L34: =PROPER(CONCATENATE(D34," ",E34," ",F34," ",G34," ",H34)) -> Warts Treatment On Chest | M34: </a> <br /> | N34: =CONCATENATE(I34,J34,K34,L34,M34) -> <a target="_blank" href="dubai.php?uae=Warts-Treatment-On-Chest">Warts Treatment On Chest </a> <br />
D35: Warts | E35: Treatment | F35: On | G35: Chin | I35: <a target="_blank" href="dubai.php?uae= | J35: =CONCATENATE(D35,$L$2,E35,$L$2,F35,$L$2,G35,H35) -> Warts-Treatment-On-Chin | K35: "> | L35: =PROPER(CONCATENATE(D35," ",E35," ",F35," ",G35," ",H35)) -> Warts Treatment On Chin | M35: </a> <br /> | N35: =CONCATENATE(I35,J35,K35,L35,M35) -> <a target="_blank" href="dubai.php?uae=Warts-Treatment-On-Chin">Warts Treatment On Chin </a> <br />
D36: Warts | E36: Treatment | F36: On | G36: Ear | I36: <a target="_blank" href="dubai.php?uae= | J36: =CONCATENATE(D36,$L$2,E36,$L$2,F36,$L$2,G36,H36) -> Warts-Treatment-On-Ear | K36: "> | L36: =PROPER(CONCATENATE(D36," ",E36," ",F36," ",G36," ",H36)) -> Warts Treatment On Ear | M36: </a> <br /> | N36: =CONCATENATE(I36,J36,K36,L36,M36) -> <a target="_blank" href="dubai.php?uae=Warts-Treatment-On-Ear">Warts Treatment On Ear </a> <br />
D37: Warts | E37: Treatment | F37: On | G37: Elbow | I37: <a target="_blank" href="dubai.php?uae= | J37: =CONCATENATE(D37,$L$2,E37,$L$2,F37,$L$2,G37,H37) -> Warts-Treatment-On-Elbow | K37: "> | L37: =PROPER(CONCATENATE(D37," ",E37," ",F37," ",G37," ",H37)) -> Warts Treatment On Elbow | M37: </a> <br /> | N37: =CONCATENATE(I37,J37,K37,L37,M37) -> <a target="_blank" href="dubai.php?uae=Warts-Treatment-On-Elbow">Warts Treatment On Elbow </a> <br />
D38: Warts | E38: Treatment | F38: On | G38: Eyebrow | I38: <a target="_blank" href="dubai.php?uae= | J38: =CONCATENATE(D38,$L$2,E38,$L$2,F38,$L$2,G38,H38) -> Warts-Treatment-On-Eyebrow | K38: "> | L38: =PROPER(CONCATENATE(D38," ",E38," ",F38," ",G38," ",H38)) -> Warts Treatment On Eyebrow | M38: </a> <br /> | N38: =CONCATENATE(I38,J38,K38,L38,M38) -> <a target="_blank" href="dubai.php?uae=Warts-Treatment-On-Eyebrow">Warts Treatment On Eyebrow </a> <br />
... D94: Shoulder | E94: Laser | F94: Warts | G94: Treatment | I94: <a target="_blank" href="dubai.php?uae= | J94: =CONCATENATE(D94,$L$2,E94,$L$2,F94,$L$2,G94,H94) -> Shoulder-Laser-Warts-Treatment | K94: "> | L94: =PROPER(CONCATENATE(D94," ",E94," ",F94," ",G94," ",H94)) -> Shoulder Laser Warts Treatment | M94: </a> <br /> | N94: =CONCATENATE(I94,J94,K94,L94,M94) -> <a target="_blank" href="dubai.php?uae=Shoulder-Laser-Warts-Treatment">Shoulder Laser Warts Treatment </a> <br />
D95: Thigh | E95: Laser | F95: Warts | G95: Treatment | I95: <a target="_blank" href="dubai.php?uae= | J95: <a target="_blank" href="dubai.php?uae= | K95: <a target="_blank" href="dubai.php?uae= | L95: <a target="_blank" href="dubai.php?uae= | M95: <a target="_blank" href="dubai.php?uae= | N95: <a target="_blank" href="dubai.php?uae=
A96: With Free Consultation | B96: -With-Free-Consultation | D96: Abdomen | E96: Laser | F96: Warts | G96: Removal | I96: <a target="_blank" href="dubai.php?uae= | J96: <a target="_blank" href="dubai.php?uae= | K96: <a target="_blank" href="dubai.php?uae= | L96: <a target="_blank" href="dubai.php?uae= | M96: <a target="_blank" href="dubai.php?uae= | N96: <a target="_blank" href="dubai.php?uae=
D97: Arm | E97: Laser | F97: Warts | G97: Removal | I97: <a target="_blank" href="dubai.php?uae= | J97: <a target="_blank" href="dubai.php?uae= | K97: <a target="_blank" href="dubai.php?uae= | L97: <a target="_blank" href="dubai.php?uae= | M97: <a target="_blank" href="dubai.php?uae= | N97: <a target="_blank" href="dubai.php?uae=
D98: Armpit | E98: Laser | F98: Warts | G98: Removal | I98: <a target="_blank" href="dubai.php?uae= | J98: <a target="_blank" href="dubai.php?uae= | K98: <a target="_blank" href="dubai.php?uae= | L98: <a target="_blank" href="dubai.php?uae= | M98: <a target="_blank" href="dubai.php?uae= | N98: <a target="_blank" href="dubai.php?uae=
D99: Back | E99: Laser | F99: Warts | G99: Removal | I99: <a target="_blank" href="dubai.php?uae= | J99: <a target="_blank" href="dubai.php?uae= | K99: <a target="_blank" href="dubai.php?uae= | L99: <a target="_blank" href="dubai.php?uae= | M99: <a target="_blank" href="dubai.php?uae= | N99: <a target="_blank" href="dubai.php?uae=
D100: Breast | E100: Laser | F100: Warts | G100: Removal | I100: <a target="_blank" href="dubai.php?uae= | J100: <a target="_blank" href="dubai.php?uae= | K100: <a target="_blank" href="dubai.php?uae= | L100: <a target="_blank" href="dubai.php?uae= | M100: <a target="_blank" href="dubai.php?uae= | N100: <a target="_blank" href="dubai.php?uae=
D101: Buttock | E101: Laser | F101: Warts | G101: Removal | I101: <a target="_blank" href="dubai.php?uae= | J101: <a target="_blank" href="dubai.php?uae= | K101: <a target="_blank" href="dubai.php?uae= | L101: <a target="_blank" href="dubai.php?uae= | M101: <a target="_blank" href="dubai.php?uae= | N101: <a target="_blank" href="dubai.php?uae=
D102: Cheek | E102: Laser | F102: Warts | G102: Removal | I102: <a target="_blank" href="dubai.php?uae= | J102: <a target="_blank" href="dubai.php?uae= | K102: <a target="_blank" href="dubai.php?uae= | L102: <a target="_blank" href="dubai.php?uae= | M102: <a target="_blank" href="dubai.php?uae= | N102: <a target="_blank" href="dubai.php?uae=
D103: Chest | E103: Laser | F103: Warts | G103: Removal | I103: <a target="_blank" href="dubai.php?uae= | J103: <a target="_blank" href="dubai.php?uae= | K103: <a target="_blank" href="dubai.php?uae= | L103: <a target="_blank" href="dubai.php?uae= | M103: <a target="_blank" href="dubai.php?uae= | N103: <a target="_blank" href="dubai.php?uae=
D104: Chin | E104: Laser | F104: Warts | G104: Removal | I104: <a target="_blank" href="dubai.php?uae= | J104: <a target="_blank" href="dubai.php?uae= | K104: <a target="_blank" href="dubai.php?uae= | L104: <a target="_blank" href="dubai.php?uae= | M104: <a target="_blank" href="dubai.php?uae= | N104: <a target="_blank" href="dubai.php?uae=
D105: Ear | E105: Laser | F105: Warts | G105: Removal | I105: <a target="_blank" href="dubai.php?uae= | J105: <a target="_blank" href="dubai.php?uae= | K105: <a target="_blank" href="dubai.php?uae= | L105: <a target="_blank" href="dubai.php?uae= | M105: <a target="_blank" href="dubai.php?uae= | N105: <a target="_blank" href="dubai.php?uae=
...

Sheet Removal Skin Tags
J1: .html | L1: blank
A2: XML Meta Tags | L2: - | M2: =LEN(L2) -> 1
C3: Body Parts | D3: Iron Welding Works
C4: Abdomen | D4: Skin | E4: Tags | F4: Removal | G4: On | H4: Abdomen | I4: <a target="_blank" href="skin_tag/ | J4: =CONCATENATE(D4,$L$2,E4,$L$2,F4,$L$2,G4,$L$2,H4,$J$1) -> Skin-Tags-Removal-On-Abdomen.html | K4: "> | L4: =PROPER(CONCATENATE(D4," ",E4," ",F4," ",G4," ",H4)) -> Skin Tags Removal On Abdomen | M4: </a> <br /> | N4: =CONCATENATE(I4,J4,K4,L4,M4) -> <a target="_blank" href="skin_tag/Skin-Tags-Removal-On-Abdomen.html">Skin Tags Removal On Abdomen</a> <br />
C5: Arm | D5: Skin | E5: Tags | F5: Removal | G5: On | H5: Arm | I5: <a target="_blank" href="skin_tag/ | J5: =CONCATENATE(D5,$L$2,E5,$L$2,F5,$L$2,G5,$L$2,H5,$J$1) -> Skin-Tags-Removal-On-Arm.html | K5: "> | L5: =PROPER(CONCATENATE(D5," ",E5," ",F5," ",G5," ",H5)) -> Skin Tags Removal On Arm | M5: </a> <br /> | N5: =CONCATENATE(I5,J5,K5,L5,M5) -> <a target="_blank" href="skin_tag/Skin-Tags-Removal-On-Arm.html">Skin Tags Removal On Arm</a> <br />
C6: Back | D6: Skin | E6: Tags | F6: Removal | G6: On | H6: Armpit | I6: <a target="_blank" href="skin_tag/ | J6: =CONCATENATE(D6,$L$2,E6,$L$2,F6,$L$2,G6,$L$2,H6,$J$1) -> Skin-Tags-Removal-On-Armpit.html | K6: "> | L6: =PROPER(CONCATENATE(D6," ",E6," ",F6," ",G6," ",H6)) -> Skin Tags Removal On Armpit | M6: </a> <br /> | N6: =CONCATENATE(I6,J6,K6,L6,M6) -> <a target="_blank" href="skin_tag/Skin-Tags-Removal-On-Armpit.html">Skin Tags Removal On Armpit</a> <br />
C7: Breast | D7: Skin | E7: Tags | F7: Removal | G7: On | H7: Back | I7: <a target="_blank" href="skin_tag/ | J7: =CONCATENATE(D7,$L$2,E7,$L$2,F7,$L$2,G7,$L$2,H7,$J$1) -> Skin-Tags-Removal-On-Back.html | K7: "> | L7: =PROPER(CONCATENATE(D7," ",E7," ",F7," ",G7," ",H7)) -> Skin Tags Removal On Back | M7: </a> <br /> | N7: =CONCATENATE(I7,J7,K7,L7,M7) -> <a target="_blank" href="skin_tag/Skin-Tags-Removal-On-Back.html">Skin Tags Removal On Back</a> <br />
C8: Buttock | D8: Skin | E8: Tags | F8: Removal | G8: On | H8: Breast | I8: <a target="_blank" href="skin_tag/ | J8: =CONCATENATE(D8,$L$2,E8,$L$2,F8,$L$2,G8,$L$2,H8,$J$1) -> Skin-Tags-Removal-On-Breast.html | K8: "> | L8: =PROPER(CONCATENATE(D8," ",E8," ",F8," ",G8," ",H8)) -> Skin Tags Removal On Breast | M8: </a> <br /> | N8: =CONCATENATE(I8,J8,K8,L8,M8) -> <a target="_blank" href="skin_tag/Skin-Tags-Removal-On-Breast.html">Skin Tags Removal On Breast</a> <br />
C9: Chest | D9: Skin | E9: Tags | F9: Removal | G9: On | H9: Buttock | I9: <a target="_blank" href="skin_tag/ | J9: =CONCATENATE(D9,$L$2,E9,$L$2,F9,$L$2,G9,$L$2,H9,$J$1) -> Skin-Tags-Removal-On-Buttock.html | K9: "> | L9: =PROPER(CONCATENATE(D9," ",E9," ",F9," ",G9," ",H9)) -> Skin Tags Removal On Buttock | M9: </a> <br /> | N9: =CONCATENATE(I9,J9,K9,L9,M9) -> <a target="_blank" href="skin_tag/Skin-Tags-Removal-On-Buttock.html">Skin Tags Removal On Buttock</a> <br />
C10: Cheek | D10: Skin | E10: Tags | F10: Removal | G10: On | H10: Cheek | I10: <a target="_blank" href="skin_tag/ | J10: =CONCATENATE(D10,$L$2,E10,$L$2,F10,$L$2,G10,$L$2,H10,$J$1) -> Skin-Tags-Removal-On-Cheek.html | K10: "> | L10: =PROPER(CONCATENATE(D10," ",E10," ",F10," ",G10," ",H10)) -> Skin Tags Removal On Cheek | M10: </a> <br /> | N10: =CONCATENATE(I10,J10,K10,L10,M10) -> <a target="_blank" href="skin_tag/Skin-Tags-Removal-On-Cheek.html">Skin Tags Removal On Cheek</a> <br />
C11: Chin | D11: Skin | E11: Tags | F11: Removal | G11: On | H11: Chest | I11: <a target="_blank" href="skin_tag/ | J11: =CONCATENATE(D11,$L$2,E11,$L$2,F11,$L$2,G11,$L$2,H11,$J$1) -> Skin-Tags-Removal-On-Chest.html | K11: "> | L11: =PROPER(CONCATENATE(D11," ",E11," ",F11," ",G11," ",H11)) -> Skin Tags Removal On Chest | M11: </a> <br /> | N11: =CONCATENATE(I11,J11,K11,L11,M11) -> <a target="_blank" href="skin_tag/Skin-Tags-Removal-On-Chest.html">Skin Tags Removal On Chest</a> <br />
